Workbook

Sheet PEDIDOS
C1: PIZZARIA BOM SUCESSO - PEDIDOS
A2: DATA | B2: PEDIDO | C2: MENU - PIZZAS | D2: PREÇO - VENDA | E2: REFRIGERANTE (OPCIONAL) | F2: PREÇO - VENDA | G2: DESCONTO | H2: TOTAL
A3: 46132 | B3: 1352 | C3: PIZZA DE MUÇARELA | D3: =VLOOKUP(C3,CONTROLE_VENDAS!$A$3:$D$9,4,0) -> 54.696 | E3: FANTA LARANJA | F3: =_xlfn.XLOOKUP(E3,CONTROLE_ESTOQUE!$A$4:$A$23,CONTROLE_ESTOQUE!$F$4:$F$23,0) -> 7.96 | H3: =D3+F3 -> 62.656
A4: 46132 | B4: 1353 | C4: PIZZA DE CALABRESA | D4: =VLOOKUP(C4,CONTROLE_VENDAS!$A$3:$D$9,4,0) -> 37.15968 | E4: FANTA UVA | F4: =_xlfn.XLOOKUP(E4,CONTROLE_ESTOQUE!$A$4:$A$23,CONTROLE_ESTOQUE!$F$4:$F$23,0) -> 7.96 | H4: =D4+F4 -> 45.11968 | J4: PIZZA DE MUÇARELA
A5: 46132 | B5: 1354 | C5: PIZZA DE FRANGO CATUPIRY | D5: =VLOOKUP(C5,CONTROLE_VENDAS!$A$3:$D$9,4,0) -> 39.96 | E5: COCA-COLA | F5: =_xlfn.XLOOKUP(E5,CONTROLE_ESTOQUE!$A$4:$A$23,CONTROLE_ESTOQUE!$F$4:$F$23,0) -> 8.96 | H5: =D5+F5 -> 48.92 | J5: PIZZA DE FRANGO CATUPIRY | L5: COCA-COLA
A6: 46132 | B6: 1355 | C6: PIZZA DE CALAMUÇA | D6: =VLOOKUP(C6,CONTROLE_VENDAS!$A$3:$D$9,4,0) -> 64.5552 | E6: GUARANA | F6: =_xlfn.XLOOKUP(E6,CONTROLE_ESTOQUE!$A$4:$A$23,CONTROLE_ESTOQUE!$F$4:$F$23,0) -> 8.96 | H6: =D6+F6 -> 73.5152 | J6: PIZZA DE CALABRESA | L6: FANTA LARANJA
A7: 46132 | B7: 1356 | C7: PIZZA DE CALAMUÇA | D7: =VLOOKUP(C7,CONTROLE_VENDAS!$A$3:$D$9,4,0) -> 64.5552 | E7: NENHUM | F7: =_xlfn.XLOOKUP(E7,CONTROLE_ESTOQUE!$A$4:$A$23,CONTROLE_ESTOQUE!$F$4:$F$23,0) -> 0 | H7: =D7+F7 -> 64.5552 | J7: PIZZA DE CALAMUÇA | L7: FANTA UVA
A8: 46132 | B8: 1357 | C8: PIZZA DE CHOC CONFETE | D8: =VLOOKUP(C8,CONTROLE_VENDAS!$A$3:$D$9,4,0) -> 18.19584 | E8: NENHUM | F8: =_xlfn.XLOOKUP(E8,CONTROLE_ESTOQUE!$A$4:$A$23,CONTROLE_ESTOQUE!$F$4:$F$23,0) -> 0 | H8: =SUM(D8,F8) -> 18.19584 | J8: PIZZA DE CHOC CONFETE | L8: GUARANA
A9: 46132 | B9: 1358 | C9: PIZZA DE CALABRESA | D9: =VLOOKUP(C9,CONTROLE_VENDAS!$A$3:$D$9,4,0) -> 37.15968 | E9: GUARANA | F9: =_xlfn.XLOOKUP(E9,CONTROLE_ESTOQUE!$A$4:$A$23,CONTROLE_ESTOQUE!$F$4:$F$23,0) -> 8.96 | H9: =D9+F9 -> 46.11968 | J9: PIZZA DE CHOC COM GRANULADO | L9: NENHUM
A10: 46132 | B10: 1359 | C10: PIZZA DE FRANGO CATUPIRY | D10: =VLOOKUP(C10,CONTROLE_VENDAS!$A$3:$D$9,4,0) -> 39.96 | E10: FANTA LARANJA | F10: =_xlfn.XLOOKUP(E10,CONTROLE_ESTOQUE!$A$4:$A$23,CONTROLE_ESTOQUE!$F$4:$F$23,0) -> 7.96 | H10: =D10+F10 -> 47.92 | J10: PIZZA DE NINHO COM MORANGO
A11: 46132 | B11: 1360 | C11: PIZZA DE CHOC COM GRANULADO | D11: =VLOOKUP(C11,CONTROLE_VENDAS!$A$3:$D$9,4,0) -> 18.5184 | E11: COCA-COLA | F11: =_xlfn.XLOOKUP(E11,CONTROLE_ESTOQUE!$A$4:$A$23,CONTROLE_ESTOQUE!$F$4:$F$23,0) -> 8.96 | H11: =D11+F11 -> 27.4784
A12: 46132 | B12: 1361 | C12: PIZZA DE CALABRESA | D12: =VLOOKUP(C12,CONTROLE_VENDAS!$A$3:$D$9,4,0) -> 37.15968 | E12: FANTA LARANJA | F12: =_xlfn.XLOOKUP(E12,CONTROLE_ESTOQUE!$A$4:$A$23,CONTROLE_ESTOQUE!$F$4:$F$23,0) -> 7.96 | H12: =D12+F12 -> 45.11968
A13: 46132 | B13: 1362 | C13: PIZZA DE CALAMUÇA | D13: =VLOOKUP(C13,CONTROLE_VENDAS!$A$3:$D$9,4,0) -> 64.5552 | E13: COCA-COLA | F13: =_xlfn.XLOOKUP(E13,CONTROLE_ESTOQUE!$A$4:$A$23,CONTROLE_ESTOQUE!$F$4:$F$23,0) -> 8.96 | H13: =D13+F13 -> 73.5152
A14: 46132 | B14: 1363 | C14: PIZZA DE FRANGO CATUPIRY | D14: =VLOOKUP(C14,CONTROLE_VENDAS!$A$3:$D$9,4,0) -> 39.96 | E14: FANTA LARANJA | F14: =_xlfn.XLOOKUP(E14,CONTROLE_ESTOQUE!$A$4:$A$23,CONTROLE_ESTOQUE!$F$4:$F$23,0) -> 7.96 | H14: =D14+F14 -> 47.92
A15: 46132 | B15: 1364 | C15: PIZZA DE CALABRESA | D15: =VLOOKUP(C15,CONTROLE_VENDAS!$A$3:$D$9,4,0) -> 37.15968 | E15: NENHUM | F15: =_xlfn.XLOOKUP(E15,CONTROLE_ESTOQUE!$A$4:$A$23,CONTROLE_ESTOQUE!$F$4:$F$23,0) -> 0 | H15: =D15+F15 -> 37.15968
A16: 46132 | B16: 1365 | C16: PIZZA DE FRANGO CATUPIRY | D16: =VLOOKUP(C16,CONTROLE_VENDAS!$A$3:$D$9,4,0) -> 39.96 | E16: FANTA UVA | F16: =_xlfn.XLOOKUP(E16,CONTROLE_ESTOQUE!$A$4:$A$23,CONTROLE_ESTOQUE!$F$4:$F$23,0) -> 7.96 | H16: =D16+F16 -> 47.92
A17: 46132 | B17: 1366 | C17: PIZZA DE NINHO COM MORANGO | D17: =VLOOKUP(C17,CONTROLE_VENDAS!$A$3:$D$9,4,0) -> 22.9536 | E17: NENHUM | F17: =_xlfn.XLOOKUP(E17,CONTROLE_ESTOQUE!$A$4:$A$23,CONTROLE_ESTOQUE!$F$4:$F$23,0) -> 0 | H17: =D17+F17 -> 22.9536
A18: 46133 | B18: 1367 | C18: PIZZA DE MUÇARELA | D18: =VLOOKUP(C18,CONTROLE_VENDAS!$A$3:$D$9,4,0) -> 54.696 | E18: FANTA LARANJA | F18: =_xlfn.XLOOKUP(E18,CONTROLE_ESTOQUE!$A$4:$A$23,CONTROLE_ESTOQUE!$F$4:$F$23,0) -> 7.96 | H18: =D18+F18 -> 62.656
D19: =VLOOKUP(C19,CONTROLE_VENDAS!$A$3:$D$9,4,0) -> #N/A | F19: =_xlfn.XLOOKUP(E19, CONTROLE_ESTOQUE!$A$4:$A$19, CONTROLE_ESTOQUE!$F$4:$F$19, 0) -> 0
D20: =VLOOKUP(C20,CONTROLE_VENDAS!$A$3:$D$9,4,0) -> #N/A | F20: =_xlfn.XLOOKUP(E20, CONTROLE_ESTOQUE!$A$4:$A$19, CONTROLE_ESTOQUE!$F$4:$F$19, 0) -> 0
D21: =VLOOKUP(C21,CONTROLE_VENDAS!$A$3:$D$9,4,0) -> #N/A | F21: =_xlfn.XLOOKUP(E21, CONTROLE_ESTOQUE!$A$4:$A$19, CONTROLE_ESTOQUE!$F$4:$F$19, 0) -> 0
D22: =VLOOKUP(C22,CONTROLE_VENDAS!$A$3:$D$9,4,0) -> #N/A | F22: =_xlfn.XLOOKUP(E22, CONTROLE_ESTOQUE!$A$4:$A$19, CONTROLE_ESTOQUE!$F$4:$F$19, 0) -> 0
D23: =VLOOKUP(C23,CONTROLE_VENDAS!$A$3:$D$9,4,0) -> #N/A | F23: =_xlfn.XLOOKUP(E23, CONTROLE_ESTOQUE!$A$4:$A$19, CONTROLE_ESTOQUE!$F$4:$F$19, 0) -> 0
D24: =VLOOKUP(C24,CONTROLE_VENDAS!$A$3:$D$9,4,0) -> #N/A | F24: =_xlfn.XLOOKUP(E24, CONTROLE_ESTOQUE!$A$4:$A$19, CONTROLE_ESTOQUE!$F$4:$F$19, 0) -> 0
D25: =VLOOKUP(C25,CONTROLE_VENDAS!$A$3:$D$9,4,0) -> #N/A | F25: =_xlfn.XLOOKUP(E25, CONTROLE_ESTOQUE!$A$4:$A$19, CONTROLE_ESTOQUE!$F$4:$F$19, 0) -> 0
D26: =VLOOKUP(C26,CONTROLE_VENDAS!$A$3:$D$9,4,0) -> #N/A | F26: =_xlfn.XLOOKUP(E26, CONTROLE_ESTOQUE!$A$4:$A$19, CONTROLE_ESTOQUE!$F$4:$F$19, 0) -> 0
D27: =VLOOKUP(C27,CONTROLE_VENDAS!$A$3:$D$9,4,0) -> #N/A | F27: =_xlfn.XLOOKUP(E27, CONTROLE_ESTOQUE!$A$4:$A$19, CONTROLE_ESTOQUE!$F$4:$F$19, 0) -> 0
D28: =VLOOKUP(C28,CONTROLE_VENDAS!$A$3:$D$9,4,0) -> #N/A | F28: =_xlfn.XLOOKUP(E28, CONTROLE_ESTOQUE!$A$4:$A$19, CONTROLE_ESTOQUE!$F$4:$F$19, 0) -> 0
D29: =VLOOKUP(C29,CONTROLE_VENDAS!$A$3:$D$9,4,0) -> #N/A | F29: =_xlfn.XLOOKUP(E29, CONTROLE_ESTOQUE!$A$4:$A$19, CONTROLE_ESTOQUE!$F$4:$F$19, 0) -> 0
D30: =VLOOKUP(C30,CONTROLE_VENDAS!$A$3:$D$9,4,0) -> #N/A | F30: =_xlfn.XLOOKUP(E30, CONTROLE_ESTOQUE!$A$4:$A$19, CONTROLE_ESTOQUE!$F$4:$F$19, 0) -> 0
... D104: =VLOOKUP(C104,CONTROLE_VENDAS!$A$3:$D$9,4,0) -> #N/A | F104: =_xlfn.XLOOKUP(E104, CONTROLE_ESTOQUE!$A$4:$A$19, CONTROLE_ESTOQUE!$F$4:$F$19, 0) -> 0
F105: =_xlfn.XLOOKUP(E105, CONTROLE_ESTOQUE!$A$4:$A$19, CONTROLE_ESTOQUE!$F$4:$F$19, 0) -> 0
F106: =_xlfn.XLOOKUP(E106, CONTROLE_ESTOQUE!$A$4:$A$19, CONTROLE_ESTOQUE!$F$4:$F$19, 0) -> 0
F107: =_xlfn.XLOOKUP(E107, CONTROLE_ESTOQUE!$A$4:$A$19, CONTROLE_ESTOQUE!$F$4:$F$19, 0) -> 0
F108: =_xlfn.XLOOKUP(E108, CONTROLE_ESTOQUE!$A$4:$A$19, CONTROLE_ESTOQUE!$F$4:$F$19, 0) -> 0
F109: =_xlfn.XLOOKUP(E109, CONTROLE_ESTOQUE!$A$4:$A$19, CONTROLE_ESTOQUE!$F$4:$F$19, 0) -> 0
F110: =_xlfn.XLOOKUP(E110, CONTROLE_ESTOQUE!$A$4:$A$19, CONTROLE_ESTOQUE!$F$4:$F$19, 0) -> 0
F111: =_xlfn.XLOOKUP(E111, CONTROLE_ESTOQUE!$A$4:$A$19, CONTROLE_ESTOQUE!$F$4:$F$19, 0) -> 0
F112: =_xlfn.XLOOKUP(E112, CONTROLE_ESTOQUE!$A$4:$A$19, CONTROLE_ESTOQUE!$F$4:$F$19, 0) -> 0
F113: =_xlfn.XLOOKUP(E113, CONTROLE_ESTOQUE!$A$4:$A$19, CONTROLE_ESTOQUE!$F$4:$F$19, 0) -> 0
...

Sheet CONTROLE_ESTOQUE
A1: #VALUE! | B1: CONTROLE DE ESTOQUE
B2: PIZZARIA - BOM SUCESSO
A3: IGREDIENTES | B3: KG/CAIXA/ML | C3: QUANTIDADE ESTOQUE | D3: SAIDA ESTOQUE | E3: TOTAL | F3: PREÇOS | G3: TOTAL | H3: STATUS (REPOSIÇÃO) | I3: Á VENCER | J3: DATA | K3: STATUS (VALIDADE)
A4: MUÇARELA | B4: KG | C4: 28 | D4: =(CONTROLE_VENDAS!$E$3*PIZZAS!C2)+(CONTROLE_VENDAS!$E$4*PIZZAS!D2)+(CONTROLE_VENDAS!$E$5*PIZZAS!E2)+(CONTROLE_VENDAS!$E$6*PIZZAS!F2)+(CONTROLE_VENDAS!$E$7*PIZZAS!G2)+(CONTROLE_VENDAS!$E$8*PIZZAS!H2)+(CONTROLE_VENDAS!$E$9*PIZZAS!I2) -> 1.2 | E4: =C4-D4 -> 26.8 | F4: 49.96 | G4: =(F4*E4) -> 1338.928 | H4: =IF(C4<20, "REPOR IMEDIATAMENTE", IF(C4<=25, "ATENÇÃO ESTOQUE", "ESTOQUE OK")) -> ESTOQUE OK | I4: 30 kg | J4: 46175 | K4: =IF(J4 <= TODAY(), "VENCIDO", IF(J4<= TODAY() + 6, "VENCE EM BREVE", "OK")) -> OK
A5: CALABRESA | B5: KG | C5: 40 | D5: =(CONTROLE_VENDAS!$E$3*PIZZAS!C3)+(CONTROLE_VENDAS!$E$4*PIZZAS!D3)+(CONTROLE_VENDAS!$E$5*PIZZAS!E3)+(CONTROLE_VENDAS!$E$6*PIZZAS!F3)+(CONTROLE_VENDAS!$E$7*PIZZAS!G3)+(CONTROLE_VENDAS!$E$8*PIZZAS!H3)+(CONTROLE_VENDAS!$E$9*PIZZAS!I3) -> 3.2 | E5: =C5-D5 -> 36.8 | F5: 19.96 | G5: =(F5*E5) -> 734.528 | H5: =IF(C5<20, "REPOR IMEDIATAMENTE", IF(C5<=25, "ATENÇÃO ESTOQUE", "ESTOQUE OK")) -> ESTOQUE OK | I5: 18 kg | J5: 46167 | K5: =IF(J5 <= TODAY(), "VENCIDO", IF(J5<= TODAY() + 6, "VENCE EM BREVE", "OK")) -> OK
A6: FARINHA | B6: KG | C6: 70 | D6: =(CONTROLE_VENDAS!$E$3*PIZZAS!C4)+(CONTROLE_VENDAS!$E$4*PIZZAS!D4)+(CONTROLE_VENDAS!$E$5*PIZZAS!E4)+(CONTROLE_VENDAS!$E$6*PIZZAS!F4)+(CONTROLE_VENDAS!$E$7*PIZZAS!G4)+(CONTROLE_VENDAS!$E$8*PIZZAS!H4)+(CONTROLE_VENDAS!$E$9*PIZZAS!I4) -> 7.35 | E6: =C6-D6 -> 62.65 | F6: 6.96 | G6: =(F6*E6) -> 436.044 | H6: =IF(C6<20, "REPOR IMEDIATAMENTE", IF(C6<=25, "ATENÇÃO ESTOQUE", "ESTOQUE OK")) -> ESTOQUE OK | I6: 2 Kg | J6: 46170 | K6: =IF(J6 <= TODAY(), "VENCIDO", IF(J6<= TODAY() + 6, "VENCE EM BREVE", "OK")) -> OK
A7: OVOS | B7: CAIXA (20 UNIDADES) | C7: 26 | D7: =(CONTROLE_VENDAS!$E$3*PIZZAS!C5)+(CONTROLE_VENDAS!$E$4*PIZZAS!D5)+(CONTROLE_VENDAS!$E$5*PIZZAS!E5)+(CONTROLE_VENDAS!$E$6*PIZZAS!F5)+(CONTROLE_VENDAS!$E$7*PIZZAS!G5)+(CONTROLE_VENDAS!$E$8*PIZZAS!H5)+(CONTROLE_VENDAS!$E$9*PIZZAS!I5) -> 84 | E7: =C7-D7 -> -58 | F7: 12.96 | G7: =(F7*E7) -> -751.68 | H7: =IF(C7<20, "REPOR IMEDIATAMENTE", IF(C7<=25, "ATENÇÃO ESTOQUE", "ESTOQUE OK")) -> ESTOQUE OK | I7: 5 cx | J7: 46141 | K7: =IF(J7 <= TODAY(), "VENCIDO", IF(J7<= TODAY() + 6, "VENCE EM BREVE", "OK")) -> VENCIDO
A8: FRANGO DESFIADO | B8: KG | C8: 36 | D8: =(CONTROLE_VENDAS!$E$3*PIZZAS!C6)+(CONTROLE_VENDAS!$E$4*PIZZAS!D6)+(CONTROLE_VENDAS!$E$5*PIZZAS!E6)+(CONTROLE_VENDAS!$E$6*PIZZAS!F6)+(CONTROLE_VENDAS!$E$7*PIZZAS!G6)+(CONTROLE_VENDAS!$E$8*PIZZAS!H6)+(CONTROLE_VENDAS!$E$9*PIZZAS!I6) -> 1 | E8: =C8-D8 -> 35 | F8: 21.96 | G8: =(F8*E8) -> 768.6 | H8: =IF(C8<20, "REPOR IMEDIATAMENTE", IF(C8<=25, "ATENÇÃO ESTOQUE", "ESTOQUE OK")) -> ESTOQUE OK | I8: 3 | J8: 46205 | K8: =IF(J8 <= TODAY(), "VENCIDO", IF(J8<= TODAY() + 6, "VENCE EM BREVE", "OK")) -> OK
A9: TOMATE | B9: KG | C9: 12 | D9: =(CONTROLE_VENDAS!$E$3*PIZZAS!C7)+(CONTROLE_VENDAS!$E$4*PIZZAS!D7)+(CONTROLE_VENDAS!$E$5*PIZZAS!E7)+(CONTROLE_VENDAS!$E$6*PIZZAS!F7)+(CONTROLE_VENDAS!$E$7*PIZZAS!G7)+(CONTROLE_VENDAS!$E$8*PIZZAS!H7)+(CONTROLE_VENDAS!$E$9*PIZZAS!I7) -> 0 | E9: =C9-D9 -> 12 | F9: 8.96 | G9: =(F9*E9) -> 107.52 | H9: =IF(C9<20, "REPOR IMEDIATAMENTE", IF(C9<=25, "ATENÇÃO ESTOQUE", "ESTOQUE OK")) -> REPOR IMEDIATAMENTE | I9: 9 | J9: 46150 | K9: =IF(J9 <= TODAY(), "VENCIDO", IF(J9<= TODAY() + 6, "VENCE EM BREVE", "OK")) -> VENCE EM BREVE
A10: CEBOLA | B10: KG | C10: 10 | D10: =(CONTROLE_VENDAS!$E$3*PIZZAS!C8)+(CONTROLE_VENDAS!$E$4*PIZZAS!D8)+(CONTROLE_VENDAS!$E$5*PIZZAS!E8)+(CONTROLE_VENDAS!$E$6*PIZZAS!F8)+(CONTROLE_VENDAS!$E$7*PIZZAS!G8)+(CONTROLE_VENDAS!$E$8*PIZZAS!H8)+(CONTROLE_VENDAS!$E$9*PIZZAS!I8) -> 0.75 | E10: =C10-D10 -> 9.25 | F10: 8.96 | G10: =(F10*E10) -> 82.88 | H10: =IF(C10<20, "REPOR IMEDIATAMENTE", IF(C10<=25, "ATENÇÃO ESTOQUE", "ESTOQUE OK")) -> REPOR IMEDIATAMENTE | I10: 7 | J10: 46146 | K10: =IF(J10 <= TODAY(), "VENCIDO", IF(J10<= TODAY() + 6, "VENCE EM BREVE", "OK")) -> VENCIDO
A11: MILHO | B11: KG | C11: 8 | D11: =(CONTROLE_VENDAS!$E$3*PIZZAS!C9)+(CONTROLE_VENDAS!$E$4*PIZZAS!D9)+(CONTROLE_VENDAS!$E$5*PIZZAS!E9)+(CONTROLE_VENDAS!$E$6*PIZZAS!F9)+(CONTROLE_VENDAS!$E$7*PIZZAS!G9)+(CONTROLE_VENDAS!$E$8*PIZZAS!H9)+(CONTROLE_VENDAS!$E$9*PIZZAS!I9) -> 0.4 | E11: =C11-D11 -> 7.6 | F11: 5.96 | G11: =(F11*E11) -> 45.296 | H11: =IF(C11<20, "REPOR IMEDIATAMENTE", IF(C11<=25, "ATENÇÃO ESTOQUE", "ESTOQUE OK")) -> REPOR IMEDIATAMENTE | I11: 8 | J11: 46232 | K11: =IF(J11 <= TODAY(), "VENCIDO", IF(J11<= TODAY() + 6, "VENCE EM BREVE", "OK")) -> OK
A12: AZEITONA | B12: KG | C12: 8 | D12: =(CONTROLE_VENDAS!$E$3*PIZZAS!C10)+(CONTROLE_VENDAS!$E$4*PIZZAS!D10)+(CONTROLE_VENDAS!$E$5*PIZZAS!E10)+(CONTROLE_VENDAS!$E$6*PIZZAS!F10)+(CONTROLE_VENDAS!$E$7*PIZZAS!G10)+(CONTROLE_VENDAS!$E$8*PIZZAS!H10)+(CONTROLE_VENDAS!$E$9*PIZZAS!I10) -> 1.5 | E12: =C12-D12 -> 6.5 | F12: 6.98 | G12: =(F12*E12) -> 45.37 | H12: =IF(C12<20, "REPOR IMEDIATAMENTE", IF(C12<=25, "ATENÇÃO ESTOQUE", "ESTOQUE OK")) -> REPOR IMEDIATAMENTE | I12: 2 | J12: 46176 | K12: =IF(J12 <= TODAY(), "VENCIDO", IF(J12<= TODAY() + 6, "VENCE EM BREVE", "OK")) -> OK
A13: MOLHO DE TOMATE | B13: KG | C13: 60 | D13: =(CONTROLE_VENDAS!$E$3*PIZZAS!C11)+(CONTROLE_VENDAS!$E$4*PIZZAS!D11)+(CONTROLE_VENDAS!$E$5*PIZZAS!E11)+(CONTROLE_VENDAS!$E$6*PIZZAS!F11)+(CONTROLE_VENDAS!$E$7*PIZZAS!G11)+(CONTROLE_VENDAS!$E$8*PIZZAS!H11)+(CONTROLE_VENDAS!$E$9*PIZZAS!I11) -> 1.5 | E13: =C13-D13 -> 58.5 | F13: 16.96 | G13: =(F13*E13) -> 992.16 | H13: =IF(C13<20, "REPOR IMEDIATAMENTE", IF(C13<=25, "ATENÇÃO ESTOQUE", "ESTOQUE OK")) -> ESTOQUE OK | I13: 4 | J13: 46241 | K13: =IF(J13 <= TODAY(), "VENCIDO", IF(J13<= TODAY() + 6, "VENCE EM BREVE", "OK")) -> OK
A14: CATUPIRY | B14: KG | C14: 12 | D14: =(CONTROLE_VENDAS!$E$3*PIZZAS!C12)+(CONTROLE_VENDAS!$E$4*PIZZAS!D12)+(CONTROLE_VENDAS!$E$5*PIZZAS!E12)+(CONTROLE_VENDAS!$E$6*PIZZAS!F12)+(CONTROLE_VENDAS!$E$7*PIZZAS!G12)+(CONTROLE_VENDAS!$E$8*PIZZAS!H12)+(CONTROLE_VENDAS!$E$9*PIZZAS!I12) -> 0.6 | E14: =C14-D14 -> 11.4 | F14: 8.96 | G14: =(F14*E14) -> 102.144 | H14: =IF(C14<20, "REPOR IMEDIATAMENTE", IF(C14<=25, "ATENÇÃO ESTOQUE", "ESTOQUE OK")) -> REPOR IMEDIATAMENTE | I14: 3 | J14: 46263 | K14: =IF(J14 <= TODAY(), "VENCIDO", IF(J14<= TODAY() + 6, "VENCE EM BREVE", "OK")) -> OK
A15: CONFETES | B15: KG | C15: 6 | D15: =(CONTROLE_VENDAS!$E$3*PIZZAS!C13)+(CONTROLE_VENDAS!$E$4*PIZZAS!D13)+(CONTROLE_VENDAS!$E$5*PIZZAS!E13)+(CONTROLE_VENDAS!$E$6*PIZZAS!F13)+(CONTROLE_VENDAS!$E$7*PIZZAS!G13)+(CONTROLE_VENDAS!$E$8*PIZZAS!H13)+(CONTROLE_VENDAS!$E$9*PIZZAS!I13) -> 0.17 | E15: =C15-D15 -> 5.83 | F15: 8.96 | G15: =(F15*E15) -> 52.2368 | H15: =IF(C15<2,"REPOR IMEDIATAMENTE","ESTOQUE OK") -> ESTOQUE OK | I15: 4 | J15: 46240 | K15: =IF(J15 <= TODAY(), "VENCIDO", IF(J15<= TODAY() + 6, "VENCE EM BREVE", "OK")) -> OK
A16: CREME DE CHOCOLATE | B16: KG | C16: 16 | D16: =(CONTROLE_VENDAS!$E$3*PIZZAS!C14)+(CONTROLE_VENDAS!$E$4*PIZZAS!D14)+(CONTROLE_VENDAS!$E$5*PIZZAS!E14)+(CONTROLE_VENDAS!$E$6*PIZZAS!F14)+(CONTROLE_VENDAS!$E$7*PIZZAS!G14)+(CONTROLE_VENDAS!$E$8*PIZZAS!H14)+(CONTROLE_VENDAS!$E$9*PIZZAS!I14) -> 0.6 | E16: =C16-D16 -> 15.4 | F16: 8.96 | G16: =(F16*E16) -> 137.984 | H16: =IF(C16<2,"REPOR IMEDIATAMENTE","ESTOQUE OK") -> ESTOQUE OK | I16: 8 | J16: 46242 | K16: =IF(J16 <= TODAY(), "VENCIDO", IF(J16<= TODAY() + 6, "VENCE EM BREVE", "OK")) -> OK
A17: GRANULADO | B17: KG | C17: 12 | D17: =(CONTROLE_VENDAS!$E$3*PIZZAS!C15)+(CONTROLE_VENDAS!$E$4*PIZZAS!D15)+(CONTROLE_VENDAS!$E$5*PIZZAS!E15)+(CONTROLE_VENDAS!$E$6*PIZZAS!F15)+(CONTROLE_VENDAS!$E$7*PIZZAS!G15)+(CONTROLE_VENDAS!$E$8*PIZZAS!H15)+(CONTROLE_VENDAS!$E$9*PIZZAS!I15) -> 0.095 | E17: =C17-D17 -> 11.905 | F17: 8.96 | G17: =(F17*E17) -> 106.6688 | H17: =IF(C17<2,"REPOR IMEDIATAMENTE","ESTOQUE OK") -> ESTOQUE OK | I17: 6 | J17: 46141 | K17: =IF(J17 <= TODAY(), "VENCIDO", IF(J17<= TODAY() + 6, "VENCE EM BREVE", "OK")) -> VENCIDO
A18: MORANGO | B18: KG | C18: 8 | D18: =(CONTROLE_VENDAS!$E$3*PIZZAS!C16)+(CONTROLE_VENDAS!$E$4*PIZZAS!D16)+(CONTROLE_VENDAS!$E$5*PIZZAS!E16)+(CONTROLE_VENDAS!$E$6*PIZZAS!F16)+(CONTROLE_VENDAS!$E$7*PIZZAS!G16)+(CONTROLE_VENDAS!$E$8*PIZZAS!H16)+(CONTROLE_VENDAS!$E$9*PIZZAS!I16) -> 0.45 | E18: =C18-D18 -> 7.55 | F18: 12.96 | G18: =(F18*E18) -> 97.848 | H18: =IF(C18<2,"REPOR IMEDIATAMENTE","ESTOQUE OK") -> ESTOQUE OK | I18: 6 | J18: 46144 | K18: =IF(J18 <= TODAY(), "VENCIDO", IF(J18<= TODAY() + 6, "VENCE EM BREVE", "OK")) -> VENCIDO
A19: CREME DE NINHO | B19: KG | C19: 12 | D19: =(CONTROLE_VENDAS!$E$3*PIZZAS!C17)+(CONTROLE_VENDAS!$E$4*PIZZAS!D17)+(CONTROLE_VENDAS!$E$5*PIZZAS!E17)+(CONTROLE_VENDAS!$E$6*PIZZAS!F17)+(CONTROLE_VENDAS!$E$7*PIZZAS!G17)+(CONTROLE_VENDAS!$E$8*PIZZAS!H17)+(CONTROLE_VENDAS!$E$9*PIZZAS!I17) -> 0.6 | E19: =C19-D19 -> 11.4 | F19: 12.96 | G19: =(F19*E19) -> 147.744 | H19: =IF(C19<2,"REPOR IMEDIATAMENTE","ESTOQUE OK") -> ESTOQUE OK | I19: 7 | J19: 46157 | K19: =IF(J19 <= TODAY(), "VENCIDO", IF(J19<= TODAY() + 6, "VENCE EM BREVE", "OK")) -> OK
A20: COCA-COLA | B20: UNIDADE | C20: =56-CONTROLE_VENDAS!J3 -> 53 | D20: =_xlfn.XLOOKUP(A20,CONTROLE_VENDAS!H3:H6,CONTROLE_VENDAS!J3:J6,0) -> 3 | E20: =C20-D20 -> 50 | F20: 8.96 | G20: =(F20*E20) -> 448 | H20: =IF(C20<20, "REPOR IMEDIATAMENTE", IF(C20<=25, "ATENÇÃO ESTOQUE", "ESTOQUE OK")) -> ESTOQUE OK | I20: 5 | J20: 46158 | K20: =IF(J20 <= TODAY(), "VENCIDO", IF(J20<= TODAY() + 6, "VENCE EM BREVE", "OK")) -> OK
A21: FANTA LARANJA | B21: UNIDADE | C21: 18 | D21: =_xlfn.XLOOKUP(A21,CONTROLE_VENDAS!H4:H7,CONTROLE_VENDAS!J4:J7,0) -> 5 | E21: =C21-D21 -> 13 | F21: 7.96 | G21: =(F21*E21) -> 103.48 | H21: =IF(C21<20, "REPOR IMEDIATAMENTE", IF(C21<=25, "ATENÇÃO ESTOQUE", "ESTOQUE OK")) -> REPOR IMEDIATAMENTE | I21: 3 | J21: 46159 | K21: =IF(J21 <= TODAY(), "VENCIDO", IF(J21<= TODAY() + 6, "VENCE EM BREVE", "OK")) -> OK
A22: FANTA UVA | B22: UNIDADE | C22: 25 | D22: =_xlfn.XLOOKUP(A22,CONTROLE_VENDAS!H5:H8,CONTROLE_VENDAS!J5:J8,0) -> 3 | E22: =C22-D22 -> 22 | F22: 7.96 | G22: =(F22*E22) -> 175.12 | H22: =IF(C22<20, "REPOR IMEDIATAMENTE", IF(C22<=25, "ATENÇÃO ESTOQUE", "ESTOQUE OK")) -> ATENÇÃO ESTOQUE | I22: 2 | J22: 46160 | K22: =IF(J22 <= TODAY(), "VENCIDO", IF(J22<= TODAY() + 6, "VENCE EM BREVE", "OK")) -> OK
A23: GUARANA | B23: UNIDADE | C23: 38 | D23: =_xlfn.XLOOKUP(A23,CONTROLE_VENDAS!H6:H9,CONTROLE_VENDAS!J6:J9,0) -> 2 | E23: =C23-D23 -> 36 | F23: 8.96 | G23: =(F23*E23) -> 322.56 | H23: =IF(C23<20, "REPOR IMEDIATAMENTE", IF(C23<=25, "ATENÇÃO ESTOQUE", "ESTOQUE OK")) -> ESTOQUE OK | I23: 4 | J23: 46161 | K23: =IF(J23 <= TODAY(), "VENCIDO", IF(J23<= TODAY() + 6, "VENCE EM BREVE", "OK")) -> OK

Sheet VALOR(RECEITA)
A1: 1309 | B1: MUÇARELA | E1: 1310 | F1: FRANGO CATUPIRY | I1: 1311 | J1: CALABRESA
A2: IGREDIENTES | B2: QUANTIDADE | C2: PREÇO | E2: IGREDIENTES | F2: QUANTIDADE | G2: VALOR | I2: IGREDIENTES | J2: QUANTIDADE | K2: VALOR
A3: FARINHA | B3: 350 | C3: =(VLOOKUP('VALOR(RECEITA)'!A3,CONTROLE_ESTOQUE!$A$3:$K$19,6,0)/1000)*B3 -> 2.436 | E3: FARINHA | F3: 350 | G3: =(VLOOKUP(E3,CONTROLE_ESTOQUE!$A$3:$K$19,6,0)/1000)*F3 -> 2.436 | I3: FARINHA | J3: 350 | K3: =(VLOOKUP(I3,CONTROLE_ESTOQUE!$A$3:$K$19,6,0)/1000)*J3 -> 2.436
A4: OVOS | B4: 4 | C4: =(VLOOKUP('VALOR(RECEITA)'!A4,CONTROLE_ESTOQUE!$A$3:$K$19,6,0)/20)*B4 -> 2.592 | E4: OVOS | F4: 4 | G4: =(VLOOKUP(E4,CONTROLE_ESTOQUE!$A$3:$K$19,6,0)/20)*F4 -> 2.592 | I4: OVOS | J4: 4 | K4: =(VLOOKUP(I4,CONTROLE_ESTOQUE!$A$3:$K$19,6,0)/20)*J4 -> 2.592
A5: MOLHO DE TOMATE | B5: 100 | C5: =(VLOOKUP('VALOR(RECEITA)'!A5,CONTROLE_ESTOQUE!$A$3:$K$19,6,0)/1000)*B5 -> 1.696 | E5: MOLHO DE TOMATE | F5: 100 | G5: =(VLOOKUP(E5,CONTROLE_ESTOQUE!$A$3:$K$19,6,0)/1000)*F5 -> 1.696 | I5: MOLHO DE TOMATE | J5: 100 | K5: =(VLOOKUP(I5,CONTROLE_ESTOQUE!$A$3:$K$19,6,0)/1000)*J5 -> 1.696
A6: MUÇARELA | B6: 200 | C6: =(VLOOKUP('VALOR(RECEITA)'!A6,CONTROLE_ESTOQUE!$A$3:$K$19,6,0)/1000)*B6 -> 9.992 | E6: FRANGO DESFIADO | F6: 350 | G6: =(VLOOKUP(E6,CONTROLE_ESTOQUE!$A$3:$K$19,6,0)/1000)*F6 -> 7.686 | I6: CALABRESA | J6: 350 | K6: =(VLOOKUP(I6,CONTROLE_ESTOQUE!$A$3:$K$19,6,0)/1000)*J6 -> 6.986
A7: TOMATE | B7: 600 | C7: =(VLOOKUP('VALOR(RECEITA)'!A7,CONTROLE_ESTOQUE!$A$3:$K$19,6,0)/1000)*B7 -> 5.376 | E7: CATUPIRY | F7: 250 | G7: =(VLOOKUP(E7,CONTROLE_ESTOQUE!$A$3:$K$19,6,0)/1000)*F7 -> 2.24 | I7: CEBOLA | J7: 120 | K7: =(VLOOKUP(I7,CONTROLE_ESTOQUE!$A$3:$K$19,6,0)/1000)*J7 -> 1.0752
A8: AZEITONA | B8: 100 | C8: =(VLOOKUP('VALOR(RECEITA)'!A8,CONTROLE_ESTOQUE!$A$3:$K$19,6,0)/1000)*B8 -> 0.698 | E8: AZEITONA | F8: 100 | G8: =(VLOOKUP(E8,CONTROLE_ESTOQUE!$A$3:$K$19,6,0)/1000)*F8 -> 0.698 | I8: AZEITONA | J8: 100 | K8: =(VLOOKUP(I8,CONTROLE_ESTOQUE!$A$3:$K$19,6,0)/1000)*J8 -> 0.698
C9: =(VLOOKUP('VALOR(RECEITA)'!A9,CONTROLE_ESTOQUE!$A$3:$K$19,5,0)/1000)*B9 -> #N/A | E9: MILHO | F9: 100 | G9: =(VLOOKUP(E9,CONTROLE_ESTOQUE!$A$3:$K$19,6,0)/1000)*F9 -> 0.596
A10: TOTAL | C10: =SUM(C3:C8) -> 22.79 | E10: TOTAL | G10: =SUM(G3:G7) -> 16.65 | I10: TOTAL | K10: =SUM(K3:K8) -> 15.4832
A12: 1312 | B12: CALAMUÇA | E12: 1313 | F12: CHOCOLATE COM CONFETE | I12: 1314 | J12: CHOCOLATE COM GRANULADO
A13: IGREDIENTES | B13: QUANTIDADE | C13: VALOR | E13: IGREDIENTES | F13: QUANTIDADE | G13: VALOR | I13: IGREDIENTES | J13: QUANTIDADE | K13: VALOR
A14: FARINHA | B14: 350 | C14: =(VLOOKUP(A14,CONTROLE_ESTOQUE!$A$3:$K$19,6,0)/1000)*'VALOR(RECEITA)'!B14 -> 2.436 | E14: FARINHA | F14: 350 | G14: =(VLOOKUP(E14,CONTROLE_ESTOQUE!$A$3:$K$19,6,0)/1000)*F14 -> 2.436 | I14: FARINHA | J14: 350 | K14: =(VLOOKUP(I14,CONTROLE_ESTOQUE!$A$3:$K$19,6,0)/1000)*J14 -> 2.436
A15: OVOS | B15: 4 | C15: =(VLOOKUP(A15,CONTROLE_ESTOQUE!$A$3:$K$19,6,0)/20)*'VALOR(RECEITA)'!B15 -> 2.592 | E15: OVOS | F15: 4 | G15: =(VLOOKUP(E15,CONTROLE_ESTOQUE!$A$3:$K$19,6,0)/20)*F15 -> 2.592 | I15: OVOS | J15: 4 | K15: =(VLOOKUP(I15,CONTROLE_ESTOQUE!$A$3:$K$19,6,0)/20)*J15 -> 2.592
A16: MOLHO DE TOMATE | B16: 100 | C16: =(VLOOKUP(A16,CONTROLE_ESTOQUE!$A$3:$K$19,6,0)/1000)*'VALOR(RECEITA)'!B16 -> 1.696 | E16: CREME DE CHOCOLATE | F16: 200 | G16: =(VLOOKUP(E16,CONTROLE_ESTOQUE!$A$3:$K$19,6,0)/1000)*F16 -> 1.792 | I16: CREME DE CHOCOLATE | J16: 200 | K16: =(VLOOKUP(I16,CONTROLE_ESTOQUE!$A$3:$K$19,6,0)/1000)*J16 -> 1.792
A17: CALABRESA | B17: 350 | C17: =(VLOOKUP(A17,CONTROLE_ESTOQUE!$A$3:$K$19,6,0)/1000)*'VALOR(RECEITA)'!B17 -> 6.986 | E17: CONFETES | F17: 85 | G17: =(VLOOKUP(E17,CONTROLE_ESTOQUE!$A$3:$K$19,6,0)/1000)*F17 -> 0.7616 | I17: GRANULADO | J17: 100 | K17: =(VLOOKUP(I17,CONTROLE_ESTOQUE!$A$3:$K$19,6,0)/1000)*J17 -> 0.896
A18: MUÇARELA | B18: 250 | C18: =(VLOOKUP(A18,CONTROLE_ESTOQUE!$A$3:$K$19,6,0)/1000)*'VALOR(RECEITA)'!B18 -> 12.49
A19: AZEITONA | B19: 100 | C19: =(VLOOKUP(A19,CONTROLE_ESTOQUE!$A$3:$K$19,6,0)/1000)*'VALOR(RECEITA)'!B19 -> 0.698
A21: TOTAL | C21: =SUM(C14:C19) -> 26.898 | E21: TOTAL | G21: =SUM(G14:G20) -> 7.5816 | I21: TOTAL | K21: =SUM(K14:K17) -> 7.716
A23: 1315 | B23: NINHO COM MORANGO
A25: FARINHA | B25: 350 | C25: =(VLOOKUP(A25,CONTROLE_ESTOQUE!$A$3:$K$19,6,0)/1000)*B25 -> 2.436
A26: OVOS | B26: 4 | C26: =(VLOOKUP(A26,CONTROLE_ESTOQUE!$A$3:$K$19,6,0)/20)*B26 -> 2.592
A27: CREME DE NINHO | B27: 200 | C27: =(VLOOKUP(A27,CONTROLE_ESTOQUE!$A$3:$K$19,6,0)/1000)*B27 -> 2.592
A28: MORANGO | B28: 150 | C28: =(VLOOKUP(A28,CONTROLE_ESTOQUE!$A$3:$K$19,6,0)/1000)*B28 -> 1.944
A32: TOTAL | C32: =SUM(C25:C28) -> 9.564

Sheet PIZZAS
A1: Ingredientes | B1: Estoque (Ref) | C1: PIZZA MUÇARELA | D1: PIZZA FRANGO CATUPIRY | E1: PIZZA CALABRESA | F1: PIZZA CALAMUÇA | G1: PIZZA CHOC. COM CONFETE | H1: PIZZA DE CHOC. COM GRANULADO | I1: PIZZA DE NINHO COM MORANGO
A2: MUÇARELA | B2: KG | C2: 0.2 | F2: 0.2
A3: CALABRESA | B3: KG | E3: 0.4 | F3: 0.4
A4: FARINHA | B4: PACOTE | C4: 0.35 | D4: 0.35 | E4: 0.35 | F4: 0.35 | G4: 0.35 | H4: 0.35 | I4: 0.35
A5: OVOS | B5: CAIXA | C5: 4 | D5: 4 | E5: 4 | F5: 4 | G5: 4 | H5: 4 | I5: 4
A6: FRANGO DESFIADO | B6: KG | D6: 0.25
A7: TOMATE | B7: KG
A8: CEBOLA | B8: KG | E8: 0.15
A9: MILHO | B9: KG | D9: 0.1
A10: AZEITONA | B10: KG | C10: 0.1 | D10: 0.1 | E10: 0.1 | F10: 0.1
A11: MOLHO DE TOMATE | B11: PACOTE | C11: 0.1 | D11: 0.1 | E11: 0.1 | F11: 0.1
A12: CATUPIRY | B12: LITRO | D12: 0.15
A13: CONFETES | B13: PACOTE | G13: 0.085
A14: CREME DE CHOCOLATE | B14: LITRO | G14: 0.2 | H14: 0.2
A15: GRANULADO | B15: PACOTE | H15: 0.095
A16: MORANGO | B16: KG | I16: 0.15
A17: CREME DE NINHO | B17: LITRO | I17: 0.2

Sheet CONTROLE_VENDAS
A1: PIZZA | B1: SAÍDAS | H1: REFRIGERANTES | I1: SAÍDAS
A2: NOME | B2: CODIGO | C2: PREÇO | D2: LUCRO 100% (VENDA) | E2: SAÍDAS | F2: TOTAL | H2: NOME | I2: PREÇO | J2: SAIDAS | K2: TOTAL
A3: PIZZA DE MUÇARELA | B3: 1309 | C3: ='VALOR(RECEITA)'!C10 -> 22.79 | D3: =(C3*$D$12)+C3 -> 54.696 | E3: =COUNTIF(PEDIDOS!C:H, "PIZZA DE MUÇARELA") -> 3 | F3: =D3*E3 -> 164.088 | H3: COCA-COLA | I3: =VLOOKUP(H3,CONTROLE_ESTOQUE!A3:I23,6,0) -> 8.96 | J3: =COUNTIF(PEDIDOS!C:H,"COCA-COLA") -> 3 | K3: =(I3*J3) -> 26.88
A4: PIZZA DE FRANGO CATUPIRY | B4: 1310 | C4: ='VALOR(RECEITA)'!G10 -> 16.65 | D4: =(C4*$D$12)+C4 -> 39.96 | E4: =COUNTIF(PEDIDOS!C:H, "PIZZA DE FRANGO CATUPIRY") -> 4 | F4: =D4*E4 -> 159.84 | H4: FANTA LARANJA | I4: =VLOOKUP(H4,CONTROLE_ESTOQUE!A4:I24,6,0) -> 7.96 | J4: =COUNTIF(PEDIDOS!C:H,"FANTA LARANJA") -> 5 | K4: =(I4*J4) -> 39.8
A5: PIZZA DE CALABRESA | B5: 1311 | C5: ='VALOR(RECEITA)'!K10 -> 15.4832 | D5: =(C5*$D$12)+C5 -> 37.15968 | E5: =COUNTIF(PEDIDOS!C:H, "PIZZA DE CALABRESA") -> 5 | F5: =D5*E5 -> 185.7984 | H5: FANTA UVA | I5: =VLOOKUP(H5,CONTROLE_ESTOQUE!A5:I25,6,0) -> 7.96 | J5: =COUNTIF(PEDIDOS!C:H,"FANTA UVA") -> 3 | K5: =(I5*J5) -> 23.88
A6: PIZZA DE CALAMUÇA | B6: 1312 | C6: ='VALOR(RECEITA)'!C21 -> 26.898 | D6: =(C6*$D$12)+C6 -> 64.5552 | E6: =COUNTIF(PEDIDOS!C:H, "PIZZA DE CALAMUÇA") -> 3 | F6: =D6*E6 -> 193.6656 | H6: GUARANA | I6: =VLOOKUP(H6,CONTROLE_ESTOQUE!A6:I26,6,0) -> 8.96 | J6: =COUNTIF(PEDIDOS!C:H,"GUARANA") -> 2 | K6: =(I6*J6) -> 17.92
A7: PIZZA DE CHOC CONFETE | B7: 1313 | C7: ='VALOR(RECEITA)'!G21 -> 7.5816 | D7: =(C7*$D$12)+C7 -> 18.19584 | E7: =COUNTIF(PEDIDOS!C:H, "PIZZA DE CHOC CONFETE") -> 2 | F7: =D7*E7 -> 36.39168 | J7: TOTAL: | K7: TOTAL:
A8: PIZZA DE CHOC COM GRANULADO | B8: 1314 | C8: ='VALOR(RECEITA)'!K21 -> 7.716 | D8: =(C8*$D$12)+C8 -> 18.5184 | E8: =COUNTIF(PEDIDOS!C:H, "PIZZA DE CHOC COM GRANULADO") -> 1 | F8: =D8*E8 -> 18.5184 | J8: =SUM(J3:J6) -> 13 | K8: =SUM(K3:K6) -> 108.48
A9: PIZZA DE NINHO COM MORANGO | B9: 1316 | C9: ='VALOR(RECEITA)'!C32 -> 9.564 | D9: =(C9*$D$12)+C9 -> 22.9536 | E9: =COUNTIF(PEDIDOS!C:H, "PIZZA DE MUÇARELA") -> 3 | F9: =D9*E9 -> 68.8608
C10: MARGEM DE LUCRO | D10: 1.2 | E10: TOTAL: | F10: TOTAL:
C11: INSUMOS | D11: 0.2 | E11: =SUM(E3:E9) -> 21 | F11: =SUM(F3:F9) -> 827.16288
C12: TOTAL | D12: =SUM(D10:D11) -> 1.4
